Workbook

Sheet Instructions
A1: Vendor Response Workbook — iWin-Type BIPV v3
A2: Purpose
A3: Use this workbook to collect vendor responses, review evidence quality, and score closure quality against the iWin pre-design pack.
A4: House rules
A5: 1. Every response must reference a revision-controlled document, drawing, report, or procedure where applicable.
A6: 2. Mark each response as contractual or informational.
A7: 3. Priority A items and all Knockout = Y rows should be treated as mandatory for credible technical screening.
A8: 4. Use the Questionnaire sheet for the raw response, Closure_Map to track blocked assumptions/design rows, and Scoring for the internal review.
A9: Sheet guide
A10: Questionnaire — vendor-facing response matrix with blank response columns.
A11: Closure_Map — maps open assumptions and design-envelope rows to the questions that close them.
A12: Scoring — internal weighted review sheet with knockout logic.

Sheet Questionnaire
A1: ID | B1: Section | C1: Priority | D1: Knockout | E1: Question | F1: Why it matters | G1: Requested response format | H1: Evidence requested | I1: Related design rows | J1: Related assumptions | K1: Vendor response | L1: Document reference | M1: Revision/date | N1: Contractual or informational | O1: Received | P1: Reviewer notes
A2: DOC-01 | B2: Document control | C2: A | D2: Y | E2: Provide the current commercial product datasheet and the full document list that governs the offered revision. | F2: Prevents mixing pilot, concept, and current commercial data. | G2: PDF datasheet + document register | H2: Datasheet, document list, revision status, issue dates | I2: S01,S02,S16,S18 | J2: A03
A3: DOC-02 | B3: Document control | C3: A | D3: Y | E3: State whether the offered product revision is identical to the one represented on the public product page and in the pilot-validation literature. If not, list all material differences. | F3: Stops false transfer of pilot or marketing claims onto a different build state. | G3: Narrative + delta table | H3: Revision-to-revision change log, superseded part list | I3: S01,S02,S10 | J3: A03,A04
A4: DOC-03 | B4: Document control | C4: B | D4: N | E4: Provide the applicable installation manual, electrical manual, maintenance manual, and troubleshooting guide. | F4: Closes serviceability and handover scope early. | G4: PDF set | H4: Manuals with revision/date | I4: S18,S19 | J4: A07,A10
A5: DOC-04 | B5: Document control | C5: B | D5: N | E5: Name the technical owner for electrical design, façade integration, controls, and warranty decisions. | F5: Needed for fast closure of cross-disciplinary items. | G5: Contact table | H5: Responsible person, role, email, authority boundary | I5: S18,S19
A6: DOC-05 | B6: Document control | C6: B | D6: N | E6: List all third-party components embedded in the offered configuration. | F6: Needed for connector, cable, electronics, and actuator traceability. | G6: BOM summary table | H6: Manufacturer, part number, function, revision, country of origin | I6: S12,S13,S14,S15 | J6: A09
A7: ARC-01 | B7: Architecture and section | C7: A | D7: Y | E7: Provide a section drawing showing outer lite, cavity/chamber, PV blind location, actuator location, feedthrough route, and replaceable boundaries. | F7: This is the master closure item for thermal path, moisture path, service boundary, and electrical exits. | G7: Section drawing | H7: Drawing PDF/DWG with dimensions, callouts, revision/date | I7: S01,S02,S13,S19 | J7: A04,A05,A07
A8: ARC-02 | B8: Architecture and section | C8: A | D8: Y | E8: State whether the PV blind sits in the main IGU cavity or in a dedicated chamber, and quantify cavity/chamber dimensions and gas/fill assumptions. | F8: Directly affects temperature, condensation risk, and optical assumptions. | G8: Structured table | H8: Section dimensions, gas or venting description, spacer concept | I8: S02,S11,S17 | J8: A04
A9: ARC-03 | B9: Architecture and section | C9: A | D9: Y | E9: Define the smallest independently replaceable unit for glazing, blind cassette, actuator, local electronics, and feedthrough hardware. | F9: Needed to estimate downtime, spares, and façade intervention size. | G9: Boundary table + diagram | H9: Replacement procedure excerpt, service drawing | I9: S19 | J9: A07,A10
A10: ARC-04 | B10: Architecture and section | C10: A | D10: Y | E10: State whether actuation is local per window, per cassette, per mullion group, or centralized across multiple windows. | F10: Changes wiring, diagnostics, controls, and common-cause failure risk. | G10: Architecture note + block diagram | H10: Control architecture drawing, power budget | I10: S12,S19 | J10: A06
A11: ARC-05 | B11: Architecture and section | C11: B | D11: N | E11: List façade integration constraints that materially affect performance or qualification (orientation, mullion depth, cavity spacing, frame material, installation tolerances). | F11: Needed so yield and thermal claims are not detached from the install context. | G11: Constraint table | H11: Installation manual extracts, tolerance table | I11: S02,S11,S17
A12: ARC-06 | B12: Architecture and section | C12: B | D12: N | E12: Describe drainage, condensation, and moisture-management paths relevant to the blind, feedthrough, and frame interfaces. | F12: Moisture path discipline is central in enclosed moving PV assemblies. | G12: Narrative + detail sketch | H12: Detail drawing, seal concept, inspection points | I12: S13,S19 | J12: A05,A10
A13: ELE-01 | B13: PV element and ratings | C13: A | D13: Y | E13: Provide the electrical datasheet for one offered window unit: Pmax, Voc, Vmp, Isc, Imp, temperature coefficients, NOCT or equivalent, maximum system voltage, and polarity conventions. | F13: No architecture screening is credible without the actual unit electrical envelope. | G13: Datasheet table | H13: Datasheet or qualified test report | I13: S03,S04,S05,S16 | J13: A03
A14: ELE-02 | B14: PV element and ratings | C14: A | D14: Y | E14: State the actual PV technology and stack used in the offered product revision, including chemistry/family, active-area fraction, and any technology-dependent constraints. | F14: The public clue 'thin-film' is insufficient for qualification, temperature, and degradation analysis. | G14: Technology declaration | H14: Manufacturer statement, cell/module datasheet, qualification path | I14: S08,S09,S10 | J14: A03
A15: ELE-03 | B15: PV element and ratings | C15: A | D15: Y | E15: Provide the internal electrical subdivision of one unit: number of slats, active slats, substrings/strings per slat or per zone, and the interconnection diagram. | F15: This is required for mismatch modeling and fault localization. | G15: Interconnect drawing + table | H15: Schematic, harness drawing, string map | I15: S03,S04,S16
A16: ELE-04 | B16: PV element and ratings | C16: A | D16: Y | E16: Provide the bypass topology and exact allocation: one diode per string, per substring, shared between strings, or another arrangement. | F16: Bypass allocation is a first-order performance and hot-spot risk variable for this product class. | G16: Topology note + schematic | H16: Schematic, part numbers, diode ratings | I16: S03,S04,S09
A17: ELE-05 | B17: PV element and ratings | C17: A | D17: Y | E17: Provide representative I–V and P–V curves for the actual product at multiple irradiance and temperature points, including at least one partial-shading or angle-dependent case. | F17: Needed to validate MPPT compatibility and mismatch assumptions. | G17: Plots + raw numeric table | H17: Test report, CSV, model basis | I17: S05,S16,S17
A18: ELE-06 | B18: PV element and ratings | C18: A | D18: Y | E18: State the allowed series and parallel aggregation limits and the design rule used to derive them. | F18: Required for Voc,max/Isc,max and for preventing unsafe or nonfunctional stringing. | G18: Aggregation rules table | H18: Application note or electrical manual | I18: S03,S04,S05
A19: ELE-07 | B19: PV element and ratings | C19: A | D19: Y | E19: State the required downstream power-conversion architecture: direct stringing, optimizer-based, modular AC, or other. Identify any architectures that are explicitly not allowed. | F19: Avoids wasting time on architectures the product cannot support. | G19: Architecture note | H19: Design manual extract, supported topologies list | I19: S05,S12
A20: ELE-08 | B20: PV element and ratings | C20: A | D20: Y | E20: Define the disconnect and isolation boundary for safe maintenance, fault finding, and unit replacement. | F20: This is a go/no-go serviceability and safety item. | G20: Single-line + service note | H20: Single-line diagram, isolation procedure, lockout note | I20: S06,S18,S19 | J20: A07
A21: ELE-09 | B21: PV element and ratings | C21: A | D21: Y | E21: State the earthing, insulation monitoring, and ground-fault or leakage-fault handling concept expected by the vendor. | F21: Needed to match inverter/PCE choice and site safety design. | G21: Protection concept note | H21: Electrical manual, example single-line, monitoring requirements | I21: S07,S12
A22: ELE-10 | B22: PV element and ratings | C22: A | D22: Y | E22: Provide frame-feedthrough details: electrical rating, dielectric path, creepage/clearance basis, strain relief, bend control, and environmental sealing. | F22: Feedthroughs are one of the highest-risk hidden interfaces in the product. | G22: Detail drawing + component table | H22: Feedthrough drawing, qualification/test basis, part numbers | I22: S13,S14,S15 | J22: A05,A09
A23: ELE-11 | B23: PV element and ratings | C23: A | D23: Y | E23: Provide the approved DC connector family, mating restrictions, and prohibited connector combinations. | F23: Connector incompatibility is a recurrent PV failure source and must be controlled contractually. | G23: Connector schedule | H23: Part numbers, ratings, installation instructions | I23: S14 | J23: A09
A24: ELE-12 | B24: PV element and ratings | C24: A | D24: Y | E24: Provide the approved cable class, insulation type, temperature rating, voltage rating, minimum bend radius, and route limitations near moving parts or warm frame zones. | F24: Needed to prevent hidden fatigue and thermal derating errors. | G24: Cable schedule | H24: Cable datasheet, route note, installation limits | I24: S15,S19 | J24: A09
A25: ELE-13 | B25: PV element and ratings | C25: B | D25: N | E25: State whether reverse-current protection, string fusing, SPDs, and surge/ESD measures are required or prohibited at the unit or group level. | F25: Clarifies BOS responsibilities and avoids unsafe default assumptions. | G25: Protection responsibility matrix | H25: Application note, single-line examples | I25: S06,S07
A26: ELE-14 | B26: PV element and ratings | C26: B | D26: N | E26: Provide expected electrical signatures for common faults such as bypass failure, open substring, loss of isolation, or wrong polarity after replacement. | F26: Improves commissioning scripts and remote diagnostics. | G26: Fault-signature table | H26: Diagnostic guide, event mapping, test data | I26: S18,S19,S20
A27: CTL-01 | B27: Controls and interfaces | C27: A | D27: Y | E27: Provide the controls architecture: local controller location, communication protocol(s), power supply requirements, and BMS/SCADA integration boundary. | F27: Controls determine both optical behavior and operational maintainability. | G27: Block diagram + I/O summary | H27: Controls architecture drawing, protocol spec | I27: S12,S18,S19 | J27: A06
A28: CTL-02 | B28: Controls and interfaces | C28: A | D28: Y | E28: Provide the point list for all measured and commanded signals: slat angle, actuator status, fault state, temperature, irradiance/light, occupancy, and communication health. | F28: Needed to verify observability and close the monitoring baseline. | G28: Point list table | H28: BMS/controls I/O list, Modbus/BACnet map | I28: S18,S19 | J28: A08
A29: CTL-03 | B29: Controls and interfaces | C29: A | D29: Y | E29: Provide actuator electrical and mechanical data: voltage, current, inrush, torque margin, duty cycle, travel time, angle resolution, and rated lifetime cycles. | F29: This is required for power sizing and reliability review. | G29: Actuator datasheet table | H29: Actuator datasheet, qualification report | I29: S12,S19 | J29: A06
A30: CTL-04 | B30: Controls and interfaces | C30: A | D30: Y | E30: State the angle-feedback method and the guaranteed error between commanded angle and actual angle over life and temperature. | F30: Angle mismatch directly degrades glare control, heat gain, and energy yield. | G30: Accuracy specification | H30: Control spec, test report | I30: S18,S19
A31: CTL-05 | B31: Controls and interfaces | C31: A | D31: Y | E31: Define fail-safe behavior for loss of sensor, loss of communications, power interruption, controller reboot, and actuator stall. | F31: Fail-safe state is a design requirement, not a commissioning detail. | G31: State table | H31: Functional safety note, controls manual | I31: S18,S19
A32: CTL-06 | B32: Controls and interfaces | C32: B | D32: N | E32: Describe manual override, local recovery, and post-fault restart behavior. | F32: Needed for facility operations and troubleshooting. | G32: Procedure note | H32: Service manual, operator guide | I32: S19
A33: CTL-07 | B33: Controls and interfaces | C33: B | D33: N | E33: Provide the alarm/event dictionary with severity classes and timestamp behavior. | F33: Makes remote fault localization realistic. | G33: Alarm list | H33: Alarm dictionary, sample logs | I33: S18,S19
A34: CTL-08 | B34: Controls and interfaces | C34: B | D34: N | E34: Provide firmware-update method, rollback method, and version traceability rules. | F34: Reduces configuration drift and upgrade risk in façade-integrated assets. | G34: Software maintenance note | H34: Firmware management procedure | I34: S19
A35: THM-01 | B35: Thermal and qualification | C35: A | D35: Y | E35: Provide measured or modeled temperatures for slat/cell, cavity/chamber air, local electronics, and frame-exit zones under representative summer and winter conditions. | F35: Thermal behavior is a first-order design unknown for glazing-integrated PV blinds. | G35: Plots + numeric table | H35: Thermal report, CFD or test report, measurement basis | I35: S11,S16,S17 | J35: A04,A08
A36: THM-02 | B36: Thermal and qualification | C36: A | D36: Y | E36: Provide declared operating limits, derating behavior, and protective thresholds for PV, electronics, and actuators. | F36: Needed to define control limits and abnormal-condition handling. | G36: Limit table | H36: Datasheet or controls protection note | I36: S11,S12
A37: THM-03 | B37: Thermal and qualification | C37: A | D37: Y | E37: Provide the qualification basis for the offered build: IEC 61730, IEC 61215, IEC TS 63126 if applicable, and any technology-specific or in-house tests actually completed. | F37: Qualification must attach to the actual offered product, not to a generic technology family. | G37: Qualification matrix | H37: Test reports, certificates, summary matrix | I37: S08,S09,S10,S11 | J37: A03
A38: THM-04 | B38: Thermal and qualification | C38: A | D38: Y | E38: Provide evidence on humidity, condensation, seal durability, and moisture tolerance relevant to the blind chamber and electrical exits. | F38: Moisture is an architecture-specific risk in enclosed moving PV assemblies. | G38: Environmental test summary | H38: Test report, climatic test matrix, inspection criteria | I38: S13,S19 | J38: A04,A05
A39: THM-05 | B39: Thermal and qualification | C39: B | D39: N | E39: State whether thermography is recommended at factory acceptance, site acceptance, or in maintenance, and define the usable inspection conditions. | F39: Closes the practical thermal-diagnostics pathway. | G39: Inspection note | H39: Thermography procedure or guidance | I39: S20
A40: THM-06 | B40: Thermal and qualification | C40: B | D40: N | E40: Provide any known installation conditions that materially increase temperature or invalidate the standard performance basis. | F40: Needed to identify high-temperature trigger conditions early. | G40: Constraint note | H40: Application note, exclusions, thermal warnings | I40: S11,S17
...

Sheet Closure_Map
A1: Closure ID | B1: Type | C1: Statement | D1: Questions covering it | E1: Closure evidence required | F1: Status | G1: Owner | H1: Notes
A2: A03 | B2: Assumption | C2: Actual PV technology and stack used | D2: ELE-01,ELE-02,THM-03 | E2: Datasheet + qualification matrix + product revision statement
A3: A04 | B3: Assumption | C3: Blind in main IGU cavity vs dedicated chamber | D3: ARC-01,ARC-02,THM-01,THM-04 | E3: Section drawing + chamber dimensions + environmental evidence
A4: A05 | B4: Assumption | C4: Electrical feedthrough exits through frame edge | D4: ARC-01,ELE-10,REL-03 | E4: Section/detail drawing + feedthrough qualification
A5: A06 | B5: Assumption | C5: Actuation architecture is local vs grouped | D5: ARC-04,CTL-01,CTL-03 | E5: Controls block diagram + actuator data
A6: A07 | B6: Assumption | C6: Unit/group can be isolated and replaced without oversized outage | D6: ARC-03,ELE-08,REL-05,REL-06,COM-02 | E6: Single-line + isolation procedure + replacement work instruction
A7: A08 | B7: Assumption | C7: Temperature sensing/observability exists or can be inferred credibly | D7: CTL-02,THM-01,COM-03 | E7: Point list + temperature evidence + acceptance limits
A8: A09 | B8: Assumption | C8: Approved connector family and cable class exist for route/environment | D8: DOC-05,ELE-10,ELE-11,ELE-12 | E8: Connector/cable schedule + datasheets + route limits
A9: A10 | B9: Assumption | C9: Low-maintenance claim does not eliminate defined service procedures | D9: DOC-03,REL-06,REL-07,BUS-01,BUS-02 | E9: Maintenance manual + replacement procedure + warranty exclusions
A10: S01 | B10: Design row | C10: BIPV module as building product | D10: DOC-01,ARC-01,THM-07 | E10: Datasheet + section drawing + building-product declarations
A11: S02 | B11: Design row | C11: BIPV system in building | D11: ARC-01,ARC-02,ARC-05,THM-07 | E11: Section/integration drawing + installation constraints
A12: S03 | B12: Design row | C12: Array voltage envelope | D12: ELE-01,ELE-03,ELE-04,ELE-06 | E12: Unit ratings + subdivision + aggregation limits
A13: S04 | B13: Design row | C13: Array current envelope | D13: ELE-01,ELE-03,ELE-06 | E13: Unit ratings + aggregation limits
... A29: S20 | B29: Design row | C29: Thermal inspection / diagnostic pathway | D29: ELE-14,THM-05,COM-03,COM-05 | E29: Fault signatures + thermography guidance + acceptance limits

Sheet Scoring
A1: ID | B1: Section | C1: Priority | D1: Knockout | E1: Weight | F1: Completeness (0-5) | G1: Evidence quality (0-5) | H1: Technical adequacy (0-5) | I1: Residual risk (0-5, higher=worse) | J1: Weighted score | K1: Knockout fail? | L1: Reviewer decision | M1: Reviewer notes
A2: =Questionnaire!A2 | B2: =Questionnaire!B2 | C2: =Questionnaire!C2 | D2: =Questionnaire!D2 | E2: =IF(C2="A",5,3) | J2: =IF(COUNTA(F2:I2)<4,"",E2*MAX(0,AVERAGE(F2:H2)-0.5*I2)) | K2: =IF(COUNTA(F2:H2)<3,"",IF(AND(D2="Y",OR(F2<3,G2<3,H2<3)),"FAIL",""))
A3: =Questionnaire!A3 | B3: =Questionnaire!B3 | C3: =Questionnaire!C3 | D3: =Questionnaire!D3 | E3: =IF(C3="A",5,3) | J3: =IF(COUNTA(F3:I3)<4,"",E3*MAX(0,AVERAGE(F3:H3)-0.5*I3)) | K3: =IF(COUNTA(F3:H3)<3,"",IF(AND(D3="Y",OR(F3<3,G3<3,H3<3)),"FAIL",""))
A4: =Questionnaire!A4 | B4: =Questionnaire!B4 | C4: =Questionnaire!C4 | D4: =Questionnaire!D4 | E4: =IF(C4="A",5,3) | J4: =IF(COUNTA(F4:I4)<4,"",E4*MAX(0,AVERAGE(F4:H4)-0.5*I4)) | K4: =IF(COUNTA(F4:H4)<3,"",IF(AND(D4="Y",OR(F4<3,G4<3,H4<3)),"FAIL",""))
A5: =Questionnaire!A5 | B5: =Questionnaire!B5 | C5: =Questionnaire!C5 | D5: =Questionnaire!D5 | E5: =IF(C5="A",5,3) | J5: =IF(COUNTA(F5:I5)<4,"",E5*MAX(0,AVERAGE(F5:H5)-0.5*I5)) | K5: =IF(COUNTA(F5:H5)<3,"",IF(AND(D5="Y",OR(F5<3,G5<3,H5<3)),"FAIL",""))
A6: =Questionnaire!A6 | B6: =Questionnaire!B6 | C6: =Questionnaire!C6 | D6: =Questionnaire!D6 | E6: =IF(C6="A",5,3) | J6: =IF(COUNTA(F6:I6)<4,"",E6*MAX(0,AVERAGE(F6:H6)-0.5*I6)) | K6: =IF(COUNTA(F6:H6)<3,"",IF(AND(D6="Y",OR(F6<3,G6<3,H6<3)),"FAIL",""))
A7: =Questionnaire!A7 | B7: =Questionnaire!B7 | C7: =Questionnaire!C7 | D7: =Questionnaire!D7 | E7: =IF(C7="A",5,3) | J7: =IF(COUNTA(F7:I7)<4,"",E7*MAX(0,AVERAGE(F7:H7)-0.5*I7)) | K7: =IF(COUNTA(F7:H7)<3,"",IF(AND(D7="Y",OR(F7<3,G7<3,H7<3)),"FAIL",""))
A8: =Questionnaire!A8 | B8: =Questionnaire!B8 | C8: =Questionnaire!C8 | D8: =Questionnaire!D8 | E8: =IF(C8="A",5,3) | J8: =IF(COUNTA(F8:I8)<4,"",E8*MAX(0,AVERAGE(F8:H8)-0.5*I8)) | K8: =IF(COUNTA(F8:H8)<3,"",IF(AND(D8="Y",OR(F8<3,G8<3,H8<3)),"FAIL",""))
A9: =Questionnaire!A9 | B9: =Questionnaire!B9 | C9: =Questionnaire!C9 | D9: =Questionnaire!D9 | E9: =IF(C9="A",5,3) | J9: =IF(COUNTA(F9:I9)<4,"",E9*MAX(0,AVERAGE(F9:H9)-0.5*I9)) | K9: =IF(COUNTA(F9:H9)<3,"",IF(AND(D9="Y",OR(F9<3,G9<3,H9<3)),"FAIL",""))
A10: =Questionnaire!A10 | B10: =Questionnaire!B10 | C10: =Questionnaire!C10 | D10: =Questionnaire!D10 | E10: =IF(C10="A",5,3) | J10: =IF(COUNTA(F10:I10)<4,"",E10*MAX(0,AVERAGE(F10:H10)-0.5*I10)) | K10: =IF(COUNTA(F10:H10)<3,"",IF(AND(D10="Y",OR(F10<3,G10<3,H10<3)),"FAIL",""))
A11: =Questionnaire!A11 | B11: =Questionnaire!B11 | C11: =Questionnaire!C11 | D11: =Questionnaire!D11 | E11: =IF(C11="A",5,3) | J11: =IF(COUNTA(F11:I11)<4,"",E11*MAX(0,AVERAGE(F11:H11)-0.5*I11)) | K11: =IF(COUNTA(F11:H11)<3,"",IF(AND(D11="Y",OR(F11<3,G11<3,H11<3)),"FAIL",""))
A12: =Questionnaire!A12 | B12: =Questionnaire!B12 | C12: =Questionnaire!C12 | D12: =Questionnaire!D12 | E12: =IF(C12="A",5,3) | J12: =IF(COUNTA(F12:I12)<4,"",E12*MAX(0,AVERAGE(F12:H12)-0.5*I12)) | K12: =IF(COUNTA(F12:H12)<3,"",IF(AND(D12="Y",OR(F12<3,G12<3,H12<3)),"FAIL",""))
A13: =Questionnaire!A13 | B13: =Questionnaire!B13 | C13: =Questionnaire!C13 | D13: =Questionnaire!D13 | E13: =IF(C13="A",5,3) | J13: =IF(COUNTA(F13:I13)<4,"",E13*MAX(0,AVERAGE(F13:H13)-0.5*I13)) | K13: =IF(COUNTA(F13:H13)<3,"",IF(AND(D13="Y",OR(F13<3,G13<3,H13<3)),"FAIL",""))
... A59: =Questionnaire!A59 | B59: =Questionnaire!B59 | C59: =Questionnaire!C59 | D59: =Questionnaire!D59 | E59: =IF(C59="A",5,3) | J59: =IF(COUNTA(F59:I59)<4,"",E59*MAX(0,AVERAGE(F59:H59)-0.5*I59)) | K59: =IF(COUNTA(F59:H59)<3,"",IF(AND(D59="Y",OR(F59<3,G59<3,H59<3)),"FAIL",""))
A62: Summary
A63: Total weighted score | B63: =SUM(J2:J59)
A64: Average weighted score | B64: =IFERROR(AVERAGEIF(J2:J59,">0"),0)
A65: Knockout fails | B65: =COUNTIF(K2:K59,"FAIL")
A66: Priority A rows unresolved | B66: =COUNTIFS(C2:C59,"A",F2:F59,"")
